<?xml version="1.0"?>
<robot name="actuator_2dof" xmlns:xacro="http://www.ros.org/wiki/xacro">

  <!-- Constants for robot dimensions -->
  <xacro:property name="PI" value="3.1415926535897931"/>
 
  <!-- Import all Gazebo-customization elements, including Gazebo colors -->
  <xacro:include filename="$(find actuator_2dof_description)/urdf/actuator_2dof.gazebo" />
  <!-- Import Rviz colors -->
  <xacro:include filename="$(find actuator_2dof_description)/urdf/materials.xacro" />

  <!-- Used for fixing robot to Gazebo 'base_link' -->
  <link name="world"/>

  <joint name="fixed" type="fixed">
    <parent link="world"/>
    <child link="base_link"/>
  </joint>


  <link name="base_link">
      <visual>
      <geometry>
        <box size="0.1 0.1 0.01"/>
      </geometry>
      <material name="black"/>
    </visual>
    <collision>
      <geometry>
        <box size="0.1 0.1 0.01"/>
      </geometry>
    </collision>
    <inertial>
      <origin xyz="0 0 0" rpy="0 0 0"/>
      <mass value="5.0"/>
      <inertia
        ixx="0.0" ixy="0.0" ixz="0.0"
        iyy="0.0" iyz="0.0"
        izz="0.0"/>
    </inertial>
  </link>

  <link name="rotating_base_link">
    <visual>
      <geometry>
        <cylinder length="0.02" radius="0.025"/>
      </geometry>
      <origin rpy="0 0 0" xyz="0 0 0.005"/>
      <material name="gray"/>
    </visual>
    <collision>
      <geometry>
        <cylinder length="0.02" radius="0.025"/>
      </geometry>
    </collision>
    <inertial>
      <origin xyz="0 0 0" rpy="0 0 0"/>
      <mass value="5.0"/>
      <inertia
        ixx="0.000947917" ixy="0.0" ixz="0.0"
        iyy="0.000947917" iyz="0.0"
        izz="0.0015625"/>
    </inertial>
  </link>

  <link name="rotating_arm_link">
    <visual>
      <geometry>
        <box size="0.005 0.0025 0.2"/>
      </geometry>
      <origin rpy="0 0 0" xyz="0 0 0.1"/>
      <material name="red"/>
    </visual>
    <collision>
      <geometry>
        <box size="0.005 0.0025 0.2"/>
      </geometry>
      <origin rpy="0 0 0" xyz="0 0 0.1"/>
    </collision>
    <inertial>
      <origin xyz="0 0 0" rpy="0 0 0"/>
      <mass value="0.1"/>
      <inertia
        ixx="0.00133333" ixy="0.0" ixz="0.0"
        iyy="0.0" iyz="0.0"
        izz="0.00133333"/>
    </inertial>
  </link>
  
  <link name="second_arm_link">
    <visual>
      <geometry>
        <box size="0.005 0.0025 0.1"/>
      </geometry>
      <origin rpy="0 0 0" xyz="0 0 0.05"/>
      <material name="green"/>
    </visual>
    <collision>
      <geometry>
        <box size="0.005 0.0025 0.1"/>
      </geometry>
      <origin rpy="0 0 0" xyz="0 0 0.05"/>
    </collision>
    <inertial>
      <origin xyz="0 0 0" rpy="0 0 0"/>
      <mass value="0.05"/>
      <inertia
        ixx="0.00016667" ixy="0.0" ixz="0.0"
        iyy="0.0" iyz="0.0"
        izz="0.00016667"/>
    </inertial>
  </link>

  <joint name="base_revolute_joint" type="continuous">
    <axis rpy="0 0 0" xyz="0 0 1"/>
    <parent link="base_link"/>
    <child link="rotating_base_link"/>
    <origin xyz="0 0 0.005"/>
  </joint>

  <joint name="upper_arm_revolute_joint" type="revolute">
    <axis xyz="1 0 0"/>
    <limit effort="100.0" lower="-1.5708" upper="1.5708" velocity="0.1"/>
    <parent link="rotating_base_link"/>
    <child link="rotating_arm_link"/>
    <origin xyz="0 0 0.01"/>
  </joint>
  
  <joint name="lower_arm_revolute_joint" type="revolute">
    <axis xyz="1 0 0"/>
    <limit effort="100.0" lower="-1.5708" upper="1.5708" velocity="0.1"/>
    <parent link="rotating_arm_link"/>
    <child link="second_arm_link"/>
    <origin xyz="0 0 0.2"/>
  </joint>

  <transmission name="base_revolute_transmission">
    <type>transmission_interface/SimpleTransmission</type>
    <joint name="base_revolute_joint">
      <hardwareInterface>hardware_interface/EffortJointInterface</hardwareInterface>
    </joint>
    <actuator name="base_revolute_motor">
      <hardwareInterface>hardware_interface/EffortJointInterface</hardwareInterface>
      <mechanicalReduction>1</mechanicalReduction>
    </actuator>
  </transmission>

  <transmission name="upper_arm_revolute_transmission">
    <type>transmission_interface/SimpleTransmission</type>
    <joint name="upper_arm_revolute_joint">
      <hardwareInterface>hardware_interface/EffortJointInterface</hardwareInterface>
    </joint>
    <actuator name="upper_arm_revolute_motor">
      <hardwareInterface>hardware_interface/EffortJointInterface</hardwareInterface>
      <mechanicalReduction>1</mechanicalReduction>
    </actuator>
  </transmission>

  <transmission name="lower_arm_revolute_transmission">
    <type>transmission_interface/SimpleTransmission</type>
    <joint name="lower_arm_revolute_joint">
      <hardwareInterface>hardware_interface/EffortJointInterface</hardwareInterface>
    </joint>
    <actuator name="lower_arm_revolute_motor">
      <hardwareInterface>hardware_interface/EffortJointInterface</hardwareInterface>
      <mechanicalReduction>1</mechanicalReduction>
    </actuator>
  </transmission>


</robot>
